Workbook

Sheet README
A1: Nagpur 20-Junction Risk Dataset | B1: Nagpur 20-Junction Risk Dataset | C1: Nagpur 20-Junction Risk Dataset | D1: Nagpur 20-Junction Risk Dataset | E1: Nagpur 20-Junction Risk Dataset | F1: Nagpur 20-Junction Risk Dataset | G1: Nagpur 20-Junction Risk Dataset | H1: Nagpur 20-Junction Risk Dataset
A2: Nagpur 20-Junction Risk Dataset | B2: Nagpur 20-Junction Risk Dataset | C2: Nagpur 20-Junction Risk Dataset | D2: Nagpur 20-Junction Risk Dataset | E2: Nagpur 20-Junction Risk Dataset | F2: Nagpur 20-Junction Risk Dataset | G2: Nagpur 20-Junction Risk Dataset | H2: Nagpur 20-Junction Risk Dataset
A4: Purpose: seed data for the AI-based traffic-risk heatmap and police-deployment decision-support prototype. | B4: Purpose: seed data for the AI-based traffic-risk heatmap and police-deployment decision-support prototype. | C4: Purpose: seed data for the AI-based traffic-risk heatmap and police-deployment decision-support prototype. | D4: Purpose: seed data for the AI-based traffic-risk heatmap and police-deployment decision-support prototype. | E4: Purpose: seed data for the AI-based traffic-risk heatmap and police-deployment decision-support prototype. | F4: Purpose: seed data for the AI-based traffic-risk heatmap and police-deployment decision-support prototype. | G4: Purpose: seed data for the AI-based traffic-risk heatmap and police-deployment decision-support prototype. | H4: Purpose: seed data for the AI-based traffic-risk heatmap and police-deployment decision-support prototype.
A6: Item | B6: Instruction / finding
A7: Primary evidence | B7: iRASTE Nagpur Detailed Report, Table 4.3. It analyzed police FIR data, geocoded blackspots and published coordinates and crash outcomes.
A8: Selected locations | B8: 20 intersections with the highest weighted-severity index among the report's intersection records.
A9: Weighted severity | B9: 5 × fatalities + 3 × major injuries + 1 × minor injuries. This is a transparent project ranking, not an official police score.
A10: Coordinate status | B10: Coordinates come from the report and pass a Nagpur bounding-box check. Each point must still be opened in OSM and marked Verified before production use.
A11: Historical period warning | B11: The report is internally inconsistent: the Table 4.3 note says 2018-2020, while an earlier passage says 2019-2021. Use 'historical FIR period; verify exact dates' in presentations.
A12: Current-risk warning | B12: Historical blackspot evidence does not prove a location is still high risk today. Recent evidence is included where located; otherwise the workbook says verification is required.
A13: Road/area context | B13: Corridor and area-context fields are derived descriptions for project organization. Verify exact road names against OpenStreetMap before importing.
A14: Real vs derived | B14: Crash counts and coordinates are source-reported. Severity index, score, rank, tier, corridor labels and risk reasons are derived. Blank dynamic inputs are for observed or simulated scenarios.
A15: Do not claim | B15: Do not present Relative Risk Score as accident probability or claim that this system predicts accidents.
A16: Next action | B16: Open each OSM link, verify the marker, correct the road/corridor name if needed, then set Manual_Map_Check to Verified.

Sheet Summary
A1: Nagpur Historical Blackspot Priority — Selected 20 | B1: Nagpur Historical Blackspot Priority — Selected 20 | C1: Nagpur Historical Blackspot Priority — Selected 20 | D1: Nagpur Historical Blackspot Priority — Selected 20 | E1: Nagpur Historical Blackspot Priority — Selected 20 | F1: Nagpur Historical Blackspot Priority — Selected 20 | G1: Nagpur Historical Blackspot Priority — Selected 20 | H1: Nagpur Historical Blackspot Priority — Selected 20 | I1: Nagpur Historical Blackspot Priority — Selected 20 | J1: Nagpur Historical Blackspot Priority — Selected 20 | K1: Nagpur Historical Blackspot Priority — Selected 20 | L1: Nagpur Historical Blackspot Priority — Selected 20 | M1: Nagpur Historical Blackspot Priority — Selected 20 | N1: Nagpur Historical Blackspot Priority — Selected 20
A2: Nagpur Historical Blackspot Priority — Selected 20 | B2: Nagpur Historical Blackspot Priority — Selected 20 | C2: Nagpur Historical Blackspot Priority — Selected 20 | D2: Nagpur Historical Blackspot Priority — Selected 20 | E2: Nagpur Historical Blackspot Priority — Selected 20 | F2: Nagpur Historical Blackspot Priority — Selected 20 | G2: Nagpur Historical Blackspot Priority — Selected 20 | H2: Nagpur Historical Blackspot Priority — Selected 20 | I2: Nagpur Historical Blackspot Priority — Selected 20 | J2: Nagpur Historical Blackspot Priority — Selected 20 | K2: Nagpur Historical Blackspot Priority — Selected 20 | L2: Nagpur Historical Blackspot Priority — Selected 20 | M2: Nagpur Historical Blackspot Priority — Selected 20 | N2: Nagpur Historical Blackspot Priority — Selected 20
A4: Selected locations | B4: =COUNTA(Junctions_20!$A$2:$A$21) -> 20
A5: Historical crashes | B5: =SUM(Junctions_20!$H$2:$H$21) -> 466
A6: Fatalities | B6: =SUM(Junctions_20!$I$2:$I$21) -> 124
A7: Major injuries | B7: =SUM(Junctions_20!$J$2:$J$21) -> 361
A9: Priority | B9: Location | C9: Risk Score | D9: Tier | E9: Fatalities
A10: =Junctions_20!N2 -> 1 | B10: =Junctions_20!B2 -> Chhatrapati Square | C10: =Junctions_20!M2 -> 100 | D10: =Junctions_20!O2 -> CRITICAL | E10: =Junctions_20!I2 -> 12
A11: =Junctions_20!N3 -> 2 | B11: =Junctions_20!B3 -> Juni Pardi Naka Chowk | C11: =Junctions_20!M3 -> 81 | D11: =Junctions_20!O3 -> CRITICAL | E11: =Junctions_20!I3 -> 13
A12: =Junctions_20!N4 -> 3 | B12: =Junctions_20!B4 -> Jhansi Rani Square | C12: =Junctions_20!M4 -> 81 | D12: =Junctions_20!O4 -> CRITICAL | E12: =Junctions_20!I4 -> 7
A13: =Junctions_20!N5 -> 4 | B13: =Junctions_20!B5 -> Jingabai Takli to Zhanda Chowk | C13: =Junctions_20!M5 -> 79 | D13: =Junctions_20!O5 -> CRITICAL | E13: =Junctions_20!I5 -> 12
A14: =Junctions_20!N6 -> 5 | B14: =Junctions_20!B6 -> Chikli Square | C14: =Junctions_20!M6 -> 72 | D14: =Junctions_20!O6 -> HIGH | E14: =Junctions_20!I6 -> 14
A15: =Junctions_20!N7 -> 6 | B15: =Junctions_20!B7 -> Maruti Seva Square, Kamptee Road | C15: =Junctions_20!M7 -> 63 | D15: =Junctions_20!O7 -> HIGH | E15: =Junctions_20!I7 -> 11
A16: =Junctions_20!N8 -> 6 | B16: =Junctions_20!B8 -> Shitla Mata Square | C16: =Junctions_20!M8 -> 63 | D16: =Junctions_20!O8 -> HIGH | E16: =Junctions_20!I8 -> 6
A17: =Junctions_20!N9 -> 8 | B17: =Junctions_20!B9 -> Kharbi Chowk | C17: =Junctions_20!M9 -> 46 | D17: =Junctions_20!O9 -> HIGH | E17: =Junctions_20!I9 -> 6
A18: =Junctions_20!N10 -> 9 | B18: =Junctions_20!B10 -> Mhalgi Nagar Square | C18: =Junctions_20!M10 -> 42 | D18: =Junctions_20!O10 -> HIGH | E18: =Junctions_20!I10 -> 4
A19: =Junctions_20!N11 -> 10 | B19: =Junctions_20!B11 -> Ravi Nagar | C19: =Junctions_20!M11 -> 41 | D19: =Junctions_20!O11 -> HIGH | E19: =Junctions_20!I11 -> 5
A21: Interpretation: these are historical FIR blackspots ranked by a transparent project severity index. A high score does not prove the junction is currently high risk. Use Evidence_Notes and complete a current field/map verification before presenting a location as current. | B21: Interpretation: these are historical FIR blackspots ranked by a transparent project severity index. A high score does not prove the junction is currently high risk. Use Evidence_Notes and complete a current field/map verification before presenting a location as current. | C21: Interpretation: these are historical FIR blackspots ranked by a transparent project severity index. A high score does not prove the junction is currently high risk. Use Evidence_Notes and complete a current field/map verification before presenting a location as current. | D21: Interpretation: these are historical FIR blackspots ranked by a transparent project severity index. A high score does not prove the junction is currently high risk. Use Evidence_Notes and complete a current field/map verification before presenting a location as current. | E21: Interpretation: these are historical FIR blackspots ranked by a transparent project severity index. A high score does not prove the junction is currently high risk. Use Evidence_Notes and complete a current field/map verification before presenting a location as current. | F21: Interpretation: these are historical FIR blackspots ranked by a transparent project severity index. A high score does not prove the junction is currently high risk. Use Evidence_Notes and complete a current field/map verification before presenting a location as current. | G21: Interpretation: these are historical FIR blackspots ranked by a transparent project severity index. A high score does not prove the junction is currently high risk. Use Evidence_Notes and complete a current field/map verification before presenting a location as current. | H21: Interpretation: these are historical FIR blackspots ranked by a transparent project severity index. A high score does not prove the junction is currently high risk. Use Evidence_Notes and complete a current field/map verification before presenting a location as current. | I21: Interpretation: these are historical FIR blackspots ranked by a transparent project severity index. A high score does not prove the junction is currently high risk. Use Evidence_Notes and complete a current field/map verification before presenting a location as current. | J21: Interpretation: these are historical FIR blackspots ranked by a transparent project severity index. A high score does not prove the junction is currently high risk. Use Evidence_Notes and complete a current field/map verification before presenting a location as current. | K21: Interpretation: these are historical FIR blackspots ranked by a transparent project severity index. A high score does not prove the junction is currently high risk. Use Evidence_Notes and complete a current field/map verification before presenting a location as current. | L21: Interpretation: these are historical FIR blackspots ranked by a transparent project severity index. A high score does not prove the junction is currently high risk. Use Evidence_Notes and complete a current field/map verification before presenting a location as current. | M21: Interpretation: these are historical FIR blackspots ranked by a transparent project severity index. A high score does not prove the junction is currently high risk. Use Evidence_Notes and complete a current field/map verification before presenting a location as current. | N21: Interpretation: these are historical FIR blackspots ranked by a transparent project severity index. A high score does not prove the junction is currently high risk. Use Evidence_Notes and complete a current field/map verification before presenting a location as current.
A22: Interpretation: these are historical FIR blackspots ranked by a transparent project severity index. A high score does not prove the junction is currently high risk. Use Evidence_Notes and complete a current field/map verification before presenting a location as current. | B22: Interpretation: these are historical FIR blackspots ranked by a transparent project severity index. A high score does not prove the junction is currently high risk. Use Evidence_Notes and complete a current field/map verification before presenting a location as current. | C22: Interpretation: these are historical FIR blackspots ranked by a transparent project severity index. A high score does not prove the junction is currently high risk. Use Evidence_Notes and complete a current field/map verification before presenting a location as current. | D22: Interpretation: these are historical FIR blackspots ranked by a transparent project severity index. A high score does not prove the junction is currently high risk. Use Evidence_Notes and complete a current field/map verification before presenting a location as current. | E22: Interpretation: these are historical FIR blackspots ranked by a transparent project severity index. A high score does not prove the junction is currently high risk. Use Evidence_Notes and complete a current field/map verification before presenting a location as current. | F22: Interpretation: these are historical FIR blackspots ranked by a transparent project severity index. A high score does not prove the junction is currently high risk. Use Evidence_Notes and complete a current field/map verification before presenting a location as current. | G22: Interpretation: these are historical FIR blackspots ranked by a transparent project severity index. A high score does not prove the junction is currently high risk. Use Evidence_Notes and complete a current field/map verification before presenting a location as current. | H22: Interpretation: these are historical FIR blackspots ranked by a transparent project severity index. A high score does not prove the junction is currently high risk. Use Evidence_Notes and complete a current field/map verification before presenting a location as current. | I22: Interpretation: these are historical FIR blackspots ranked by a transparent project severity index. A high score does not prove the junction is currently high risk. Use Evidence_Notes and complete a current field/map verification before presenting a location as current. | J22: Interpretation: these are historical FIR blackspots ranked by a transparent project severity index. A high score does not prove the junction is currently high risk. Use Evidence_Notes and complete a current field/map verification before presenting a location as current. | K22: Interpretation: these are historical FIR blackspots ranked by a transparent project severity index. A high score does not prove the junction is currently high risk. Use Evidence_Notes and complete a current field/map verification before presenting a location as current. | L22: Interpretation: these are historical FIR blackspots ranked by a transparent project severity index. A high score does not prove the junction is currently high risk. Use Evidence_Notes and complete a current field/map verification before presenting a location as current. | M22: Interpretation: these are historical FIR blackspots ranked by a transparent project severity index. A high score does not prove the junction is currently high risk. Use Evidence_Notes and complete a current field/map verification before presenting a location as current. | N22: Interpretation: these are historical FIR blackspots ranked by a transparent project severity index. A high score does not prove the junction is currently high risk. Use Evidence_Notes and complete a current field/map verification before presenting a location as current.
A23: Interpretation: these are historical FIR blackspots ranked by a transparent project severity index. A high score does not prove the junction is currently high risk. Use Evidence_Notes and complete a current field/map verification before presenting a location as current. | B23: Interpretation: these are historical FIR blackspots ranked by a transparent project severity index. A high score does not prove the junction is currently high risk. Use Evidence_Notes and complete a current field/map verification before presenting a location as current. | C23: Interpretation: these are historical FIR blackspots ranked by a transparent project severity index. A high score does not prove the junction is currently high risk. Use Evidence_Notes and complete a current field/map verification before presenting a location as current. | D23: Interpretation: these are historical FIR blackspots ranked by a transparent project severity index. A high score does not prove the junction is currently high risk. Use Evidence_Notes and complete a current field/map verification before presenting a location as current. | E23: Interpretation: these are historical FIR blackspots ranked by a transparent project severity index. A high score does not prove the junction is currently high risk. Use Evidence_Notes and complete a current field/map verification before presenting a location as current. | F23: Interpretation: these are historical FIR blackspots ranked by a transparent project severity index. A high score does not prove the junction is currently high risk. Use Evidence_Notes and complete a current field/map verification before presenting a location as current. | G23: Interpretation: these are historical FIR blackspots ranked by a transparent project severity index. A high score does not prove the junction is currently high risk. Use Evidence_Notes and complete a current field/map verification before presenting a location as current. | H23: Interpretation: these are historical FIR blackspots ranked by a transparent project severity index. A high score does not prove the junction is currently high risk. Use Evidence_Notes and complete a current field/map verification before presenting a location as current. | I23: Interpretation: these are historical FIR blackspots ranked by a transparent project severity index. A high score does not prove the junction is currently high risk. Use Evidence_Notes and complete a current field/map verification before presenting a location as current. | J23: Interpretation: these are historical FIR blackspots ranked by a transparent project severity index. A high score does not prove the junction is currently high risk. Use Evidence_Notes and complete a current field/map verification before presenting a location as current. | K23: Interpretation: these are historical FIR blackspots ranked by a transparent project severity index. A high score does not prove the junction is currently high risk. Use Evidence_Notes and complete a current field/map verification before presenting a location as current. | L23: Interpretation: these are historical FIR blackspots ranked by a transparent project severity index. A high score does not prove the junction is currently high risk. Use Evidence_Notes and complete a current field/map verification before presenting a location as current. | M23: Interpretation: these are historical FIR blackspots ranked by a transparent project severity index. A high score does not prove the junction is currently high risk. Use Evidence_Notes and complete a current field/map verification before presenting a location as current. | N23: Interpretation: these are historical FIR blackspots ranked by a transparent project severity index. A high score does not prove the junction is currently high risk. Use Evidence_Notes and complete a current field/map verification before presenting a location as current.
A24: Interpretation: these are historical FIR blackspots ranked by a transparent project severity index. A high score does not prove the junction is currently high risk. Use Evidence_Notes and complete a current field/map verification before presenting a location as current. | B24: Interpretation: these are historical FIR blackspots ranked by a transparent project severity index. A high score does not prove the junction is currently high risk. Use Evidence_Notes and complete a current field/map verification before presenting a location as current. | C24: Interpretation: these are historical FIR blackspots ranked by a transparent project severity index. A high score does not prove the junction is currently high risk. Use Evidence_Notes and complete a current field/map verification before presenting a location as current. | D24: Interpretation: these are historical FIR blackspots ranked by a transparent project severity index. A high score does not prove the junction is currently high risk. Use Evidence_Notes and complete a current field/map verification before presenting a location as current. | E24: Interpretation: these are historical FIR blackspots ranked by a transparent project severity index. A high score does not prove the junction is currently high risk. Use Evidence_Notes and complete a current field/map verification before presenting a location as current. | F24: Interpretation: these are historical FIR blackspots ranked by a transparent project severity index. A high score does not prove the junction is currently high risk. Use Evidence_Notes and complete a current field/map verification before presenting a location as current. | G24: Interpretation: these are historical FIR blackspots ranked by a transparent project severity index. A high score does not prove the junction is currently high risk. Use Evidence_Notes and complete a current field/map verification before presenting a location as current. | H24: Interpretation: these are historical FIR blackspots ranked by a transparent project severity index. A high score does not prove the junction is currently high risk. Use Evidence_Notes and complete a current field/map verification before presenting a location as current. | I24: Interpretation: these are historical FIR blackspots ranked by a transparent project severity index. A high score does not prove the junction is currently high risk. Use Evidence_Notes and complete a current field/map verification before presenting a location as current. | J24: Interpretation: these are historical FIR blackspots ranked by a transparent project severity index. A high score does not prove the junction is currently high risk. Use Evidence_Notes and complete a current field/map verification before presenting a location as current. | K24: Interpretation: these are historical FIR blackspots ranked by a transparent project severity index. A high score does not prove the junction is currently high risk. Use Evidence_Notes and complete a current field/map verification before presenting a location as current. | L24: Interpretation: these are historical FIR blackspots ranked by a transparent project severity index. A high score does not prove the junction is currently high risk. Use Evidence_Notes and complete a current field/map verification before presenting a location as current. | M24: Interpretation: these are historical FIR blackspots ranked by a transparent project severity index. A high score does not prove the junction is currently high risk. Use Evidence_Notes and complete a current field/map verification before presenting a location as current. | N24: Interpretation: these are historical FIR blackspots ranked by a transparent project severity index. A high score does not prove the junction is currently high risk. Use Evidence_Notes and complete a current field/map verification before presenting a location as current.

Sheet Junctions_20
A1: Junction_ID | B1: Location_Name | C1: Latitude | D1: Longitude | E1: Section_Type | F1: Corridor_or_Area_Derived | G1: Area_Context_Derived | H1: Historical_Crashes | I1: Fatalities | J1: Major_Injuries | K1: Minor_Injuries | L1: Weighted_Severity_Index | M1: Relative_Risk_Score_0_100 | N1: Priority_Rank | O1: Historical_Priority_Tier | P1: Coordinate_QA | Q1: Manual_Map_Check | R1: OSM_Map_URL | S1: Data_Period | T1: Data_Classification | U1: Base_Source_ID | V1: Evidence_Source_ID | W1: Import_Ready | X1: User_Notes
A2: J001 | B2: Chhatrapati Square | C2: 21.11083 | D2: 79.07011 | E2: Intersection | F2: Wardha Road / Inner Ring Road area | G2: Mixed transport and residential | H2: 45 | I2: 12 | J2: 37 | K2: 9 | L2: =I2*5+J2*3+K2 -> 180 | M2: =ROUND(L2/MAX($L$2:$L$21)*100,0) -> 100 | N2: =COUNTIF($L$2:$L$21,">"&L2)+1 -> 1 | O2: =IF(N2<=4,"CRITICAL",IF(N2<=10,"HIGH",IF(N2<=16,"MEDIUM","ELEVATED"))) -> CRITICAL | P2: =IF(AND(C2>=20.9,C2<=21.25,D2>=78.9,D2<=79.25),"PASS","CHECK") -> PASS | Q2: Verified | R2: https://www.openstreetmap.org/?mlat=21.11083&mlon=79.07011#map=18/21.11083/79.07011 | S2: Historical FIR period; report date inconsistency noted | T2: REAL source values + DERIVED ranking/context | U2: S01 | V2: S03 | W2: =IF(AND(P2="PASS",Q2="Verified"),"YES","REVIEW") -> YES
A3: J002 | B3: Juni Pardi Naka Chowk | C3: 21.15139 | D3: 79.14889 | E3: Intersection | F3: Old Pardi Naka / Bhandara Road corridor | G3: Highway-commercial-industrial mix | H3: 33 | I3: 13 | J3: 25 | K3: 6 | L3: =I3*5+J3*3+K3 -> 146 | M3: =ROUND(L3/MAX($L$2:$L$21)*100,0) -> 81 | N3: =COUNTIF($L$2:$L$21,">"&L3)+1 -> 2 | O3: =IF(N3<=4,"CRITICAL",IF(N3<=10,"HIGH",IF(N3<=16,"MEDIUM","ELEVATED"))) -> CRITICAL | P3: =IF(AND(C3>=20.9,C3<=21.25,D3>=78.9,D3<=79.25),"PASS","CHECK") -> PASS | Q3: Verified | R3: https://www.openstreetmap.org/?mlat=21.15139&mlon=79.14889#map=18/21.15139/79.14889 | S3: Historical FIR period; report date inconsistency noted | T3: REAL source values + DERIVED ranking/context | U3: S01 | V3: S03 | W3: =IF(AND(P3="PASS",Q3="Verified"),"YES","REVIEW") -> YES
A4: J003 | B4: Jhansi Rani Square | C4: 21.14124 | D4: 79.08029 | E4: Intersection | F4: Ramdaspeth-Sitabuldi / North Ambazari Road | G4: CBD and public-transport hub | H4: 41 | I4: 7 | J4: 35 | K4: 5 | L4: =I4*5+J4*3+K4 -> 145 | M4: =ROUND(L4/MAX($L$2:$L$21)*100,0) -> 81 | N4: =COUNTIF($L$2:$L$21,">"&L4)+1 -> 3 | O4: =IF(N4<=4,"CRITICAL",IF(N4<=10,"HIGH",IF(N4<=16,"MEDIUM","ELEVATED"))) -> CRITICAL | P4: =IF(AND(C4>=20.9,C4<=21.25,D4>=78.9,D4<=79.25),"PASS","CHECK") -> PASS | Q4: Verified | R4: https://www.openstreetmap.org/?mlat=21.14124&mlon=79.08029#map=18/21.14124/79.08029 | S4: Historical FIR period; report date inconsistency noted | T4: REAL source values + DERIVED ranking/context | U4: S01 | V4: S06 | W4: =IF(AND(P4="PASS",Q4="Verified"),"YES","REVIEW") -> YES
A5: J004 | B5: Jingabai Takli to Zhanda Chowk | C5: 21.18761 | D5: 79.07888 | E5: Intersection | F5: Jingabai Takli-Zhanda Chowk corridor | G5: Residential and urban arterial | H5: 39 | I5: 12 | J5: 25 | K5: 8 | L5: =I5*5+J5*3+K5 -> 143 | M5: =ROUND(L5/MAX($L$2:$L$21)*100,0) -> 79 | N5: =COUNTIF($L$2:$L$21,">"&L5)+1 -> 4 | O5: =IF(N5<=4,"CRITICAL",IF(N5<=10,"HIGH",IF(N5<=16,"MEDIUM","ELEVATED"))) -> CRITICAL | P5: =IF(AND(C5>=20.9,C5<=21.25,D5>=78.9,D5<=79.25),"PASS","CHECK") -> PASS | Q5: Verified | R5: https://www.openstreetmap.org/?mlat=21.18761&mlon=79.07888#map=18/21.18761/79.07888 | S5: Historical FIR period; report date inconsistency noted | T5: REAL source values + DERIVED ranking/context | U5: S01 | V5: S01 | W5: =IF(AND(P5="PASS",Q5="Verified"),"YES","REVIEW") -> YES
A6: J005 | B6: Chikli Square | C6: 21.1623 | D6: 79.14106 | E6: Intersection | F6: Inner Ring Road / Chikhli-Kalamna side | G6: Industrial-logistics and residential mix | H6: 31 | I6: 14 | J6: 18 | K6: 5 | L6: =I6*5+J6*3+K6 -> 129 | M6: =ROUND(L6/MAX($L$2:$L$21)*100,0) -> 72 | N6: =COUNTIF($L$2:$L$21,">"&L6)+1 -> 5 | O6: =IF(N6<=4,"CRITICAL",IF(N6<=10,"HIGH",IF(N6<=16,"MEDIUM","ELEVATED"))) -> HIGH | P6: =IF(AND(C6>=20.9,C6<=21.25,D6>=78.9,D6<=79.25),"PASS","CHECK") -> PASS | Q6: Verified | R6: https://www.openstreetmap.org/?mlat=21.1623&mlon=79.14106#map=18/21.1623/79.14106 | S6: Historical FIR period; report date inconsistency noted | T6: REAL source values + DERIVED ranking/context | U6: S01 | V6: S07 | W6: =IF(AND(P6="PASS",Q6="Verified"),"YES","REVIEW") -> YES
A7: J006 | B7: Maruti Seva Square, Kamptee Road | C7: 21.18391 | D7: 79.11693 | E7: Intersection | F7: Kamptee Road | G7: Highway-commercial and five-road junction | H7: 27 | I7: 11 | J7: 19 | K7: 2 | L7: =I7*5+J7*3+K7 -> 114 | M7: =ROUND(L7/MAX($L$2:$L$21)*100,0) -> 63 | N7: =COUNTIF($L$2:$L$21,">"&L7)+1 -> 6 | O7: =IF(N7<=4,"CRITICAL",IF(N7<=10,"HIGH",IF(N7<=16,"MEDIUM","ELEVATED"))) -> HIGH | P7: =IF(AND(C7>=20.9,C7<=21.25,D7>=78.9,D7<=79.25),"PASS","CHECK") -> PASS | Q7: Verified | R7: https://www.openstreetmap.org/?mlat=21.18391&mlon=79.11693#map=18/21.18391/79.11693 | S7: Historical FIR period; report date inconsistency noted | T7: REAL source values + DERIVED ranking/context | U7: S01 | V7: S03 | W7: =IF(AND(P7="PASS",Q7="Verified"),"YES","REVIEW") -> YES
A8: J007 | B8: Shitla Mata Square | C8: 21.12194 | D8: 79.12111 | E8: Intersection | F8: East Nagpur urban corridor | G8: Dense mixed residential-commercial | H8: 27 | I8: 6 | J8: 27 | K8: 3 | L8: =I8*5+J8*3+K8 -> 114 | M8: =ROUND(L8/MAX($L$2:$L$21)*100,0) -> 63 | N8: =COUNTIF($L$2:$L$21,">"&L8)+1 -> 6 | O8: =IF(N8<=4,"CRITICAL",IF(N8<=10,"HIGH",IF(N8<=16,"MEDIUM","ELEVATED"))) -> HIGH | P8: =IF(AND(C8>=20.9,C8<=21.25,D8>=78.9,D8<=79.25),"PASS","CHECK") -> PASS | Q8: Verified | R8: https://www.openstreetmap.org/?mlat=21.12194&mlon=79.12111#map=18/21.12194/79.12111 | S8: Historical FIR period; report date inconsistency noted | T8: REAL source values + DERIVED ranking/context | U8: S01 | V8: S01 | W8: =IF(AND(P8="PASS",Q8="Verified"),"YES","REVIEW") -> YES
A9: J008 | B9: Kharbi Chowk | C9: 21.12425 | D9: 79.13848 | E9: Intersection | F9: Kharbi / Inner Ring Road area | G9: Residential-commercial urban arterial | H9: 21 | I9: 6 | J9: 16 | K9: 4 | L9: =I9*5+J9*3+K9 -> 82 | M9: =ROUND(L9/MAX($L$2:$L$21)*100,0) -> 46 | N9: =COUNTIF($L$2:$L$21,">"&L9)+1 -> 8 | O9: =IF(N9<=4,"CRITICAL",IF(N9<=10,"HIGH",IF(N9<=16,"MEDIUM","ELEVATED"))) -> HIGH | P9: =IF(AND(C9>=20.9,C9<=21.25,D9>=78.9,D9<=79.25),"PASS","CHECK") -> PASS | Q9: Verified | R9: https://www.openstreetmap.org/?mlat=21.12425&mlon=79.13848#map=18/21.12425/79.13848 | S9: Historical FIR period; report date inconsistency noted | T9: REAL source values + DERIVED ranking/context | U9: S01 | V9: S01 | W9: =IF(AND(P9="PASS",Q9="Verified"),"YES","REVIEW") -> YES
A10: J009 | B10: Mhalgi Nagar Square | C10: 21.10766 | D10: 79.11961 | E10: Intersection | F10: Mhalgi Nagar / Ring Road-Umred Road side | G10: Residential-commercial arterial | H10: 18 | I10: 4 | J10: 18 | K10: 1 | L10: =I10*5+J10*3+K10 -> 75 | M10: =ROUND(L10/MAX($L$2:$L$21)*100,0) -> 42 | N10: =COUNTIF($L$2:$L$21,">"&L10)+1 -> 9 | O10: =IF(N10<=4,"CRITICAL",IF(N10<=10,"HIGH",IF(N10<=16,"MEDIUM","ELEVATED"))) -> HIGH | P10: =IF(AND(C10>=20.9,C10<=21.25,D10>=78.9,D10<=79.25),"PASS","CHECK") -> PASS | Q10: Verified | R10: https://www.openstreetmap.org/?mlat=21.10766&mlon=79.11961#map=18/21.10766/79.11961 | S10: Historical FIR period; report date inconsistency noted | T10: REAL source values + DERIVED ranking/context | U10: S01 | V10: S03 | W10: =IF(AND(P10="PASS",Q10="Verified"),"YES","REVIEW") -> YES
A11: J010 | B11: Ravi Nagar | C11: 21.14744 | D11: 79.0562 | E11: Intersection | F11: Ravi Nagar / Amravati Road area | G11: Commercial-residential and transport | H11: 26 | I11: 5 | J11: 14 | K11: 7 | L11: =I11*5+J11*3+K11 -> 74 | M11: =ROUND(L11/MAX($L$2:$L$21)*100,0) -> 41 | N11: =COUNTIF($L$2:$L$21,">"&L11)+1 -> 10 | O11: =IF(N11<=4,"CRITICAL",IF(N11<=10,"HIGH",IF(N11<=16,"MEDIUM","ELEVATED"))) -> HIGH | P11: =IF(AND(C11>=20.9,C11<=21.25,D11>=78.9,D11<=79.25),"PASS","CHECK") -> PASS | Q11: Verified | R11: https://www.openstreetmap.org/?mlat=21.14744&mlon=79.0562#map=18/21.14744/79.0562 | S11: Historical FIR period; report date inconsistency noted | T11: REAL source values + DERIVED ranking/context | U11: S01 | V11: S01 | W11: =IF(AND(P11="PASS",Q11="Verified"),"YES","REVIEW") -> YES
A12: J011 | B12: Manewada Square | C12: 21.10522 | D12: 79.10247 | E12: Intersection | F12: Inner Ring Road / Manewada Road | G12: Dense residential-commercial arterial | H12: 18 | I12: 2 | J12: 19 | K12: 3 | L12: =I12*5+J12*3+K12 -> 70 | M12: =ROUND(L12/MAX($L$2:$L$21)*100,0) -> 39 | N12: =COUNTIF($L$2:$L$21,">"&L12)+1 -> 11 | O12: =IF(N12<=4,"CRITICAL",IF(N12<=10,"HIGH",IF(N12<=16,"MEDIUM","ELEVATED"))) -> MEDIUM | P12: =IF(AND(C12>=20.9,C12<=21.25,D12>=78.9,D12<=79.25),"PASS","CHECK") -> PASS | Q12: Verified | R12: https://www.openstreetmap.org/?mlat=21.10522&mlon=79.10247#map=18/21.10522/79.10247 | S12: Historical FIR period; report date inconsistency noted | T12: REAL source values + DERIVED ranking/context | U12: S01 | V12: S03 | W12: =IF(AND(P12="PASS",Q12="Verified"),"YES","REVIEW") -> YES
A13: J012 | B13: Chinchbhavan Square | C13: 21.0675 | D13: 79.05833 | E13: Intersection | F13: Wardha Road / Chinchbhavan | G13: Highway-residential and airport-side traffic | H13: 15 | I13: 3 | J13: 14 | K13: 5 | L13: =I13*5+J13*3+K13 -> 62 | M13: =ROUND(L13/MAX($L$2:$L$21)*100,0) -> 34 | N13: =COUNTIF($L$2:$L$21,">"&L13)+1 -> 12 | O13: =IF(N13<=4,"CRITICAL",IF(N13<=10,"HIGH",IF(N13<=16,"MEDIUM","ELEVATED"))) -> MEDIUM | P13: =IF(AND(C13>=20.9,C13<=21.25,D13>=78.9,D13<=79.25),"PASS","CHECK") -> PASS | Q13: Verified | R13: https://www.openstreetmap.org/?mlat=21.0675&mlon=79.05833#map=18/21.0675/79.05833 | S13: Historical FIR period; report date inconsistency noted | T13: REAL source values + DERIVED ranking/context | U13: S01 | V13: S03 | W13: =IF(AND(P13="PASS",Q13="Verified"),"YES","REVIEW") -> YES
... A21: J020 | B21: Auto Hub to Toll Naka | C21: 21.15352 | D21: 79.00419 | E21: Intersection | F21: Wadi / Amravati Road toll corridor | G21: Highway-industrial and logistics traffic | H21: 12 | I21: 4 | J21: 10 | K21: 1 | L21: =I21*5+J21*3+K21 -> 51 | M21: =ROUND(L21/MAX($L$2:$L$21)*100,0) -> 28 | N21: =COUNTIF($L$2:$L$21,">"&L21)+1 -> 20 | O21: =IF(N21<=4,"CRITICAL",IF(N21<=10,"HIGH",IF(N21<=16,"MEDIUM","ELEVATED"))) -> ELEVATED | P21: =IF(AND(C21>=20.9,C21<=21.25,D21>=78.9,D21<=79.25),"PASS","CHECK") -> PASS | Q21: Verified | R21: https://www.openstreetmap.org/?mlat=21.15352&mlon=79.00419#map=18/21.15352/79.00419 | S21: Historical FIR period; report date inconsistency noted | T21: REAL source values + DERIVED ranking/context | U21: S01 | V21: S01 | W21: =IF(AND(P21="PASS",Q21="Verified"),"YES","REVIEW") -> YES

Sheet Evidence_Notes
A1: Junction_ID | B1: Location_Name | C1: Valid_Risk_Reason | D1: Recent_Evidence_or_Status | E1: Interpretation | F1: Primary_Source_URL | G1: Secondary_Source_URL | H1: Confidence | I1: Verification_Needed
A2: J001 | B2: Chhatrapati Square | C2: Police-FIR blackspot evidence: 45 crashes, 12 fatalities, 37 major injuries and 9 minor injuries in the source table. The location was selected under the report's MoRTH blackspot methodology; the workbook rank is derived from severity outcomes. | D2: Listed with 3 serious accidents in the 2021-2023 update; newer road-condition concerns require field verification. | E2: Strong historical evidence; current classification requires new observation or official record. | F2: https://www.inai.ai/img/docs/iraste-nagpur/iRASATE-Detailed-Report.pdf | G2: https://www.thehitavada.com/Encyc/2024/12/10/Prakash-High-School-to-Kapsi-Bridge-MarutiShowroom-sq-among.html | H2: MEDIUM | I2: Manual map check + current traffic observation
A3: J002 | B3: Juni Pardi Naka Chowk | C3: Police-FIR blackspot evidence: 33 crashes, 13 fatalities, 25 major injuries and 6 minor injuries in the source table. The location was selected under the report's MoRTH blackspot methodology; the workbook rank is derived from severity outcomes. | D3: 2024 reporting lists Old Pardi Naka with 8 serious accidents; the wider Pardi cluster remained a major concern. | E3: Historical evidence plus newer location-specific support; still verify the latest field condition. | F3: https://www.inai.ai/img/docs/iraste-nagpur/iRASATE-Detailed-Report.pdf | G3: https://www.thehitavada.com/Encyc/2024/12/10/Prakash-High-School-to-Kapsi-Bridge-MarutiShowroom-sq-among.html | H3: MEDIUM-HIGH | I3: Manual map check + current traffic observation
A4: J003 | B4: Jhansi Rani Square | C4: Police-FIR blackspot evidence: 41 crashes, 7 fatalities, 35 major injuries and 5 minor injuries in the source table. The location was selected under the report's MoRTH blackspot methodology; the workbook rank is derived from severity outcomes. | D4: 2024 reporting describes daily congestion from autorickshaw parking, encroachment and wrong-side driving. | E4: Historical evidence plus newer location-specific support; still verify the latest field condition. | F4: https://www.inai.ai/img/docs/iraste-nagpur/iRASATE-Detailed-Report.pdf | G4: https://timesofindia.indiatimes.com/city/nagpur/traffic-chaos-at-jhansi-rani-square-in-nagpur/articleshow/113175497.cms | H4: MEDIUM-HIGH | I4: Manual map check + current traffic observation
A5: J004 | B5: Jingabai Takli to Zhanda Chowk | C5: Police-FIR blackspot evidence: 39 crashes, 12 fatalities, 25 major injuries and 8 minor injuries in the source table. The location was selected under the report's MoRTH blackspot methodology; the workbook rank is derived from severity outcomes. | D5: No row-specific 2024-2026 count located during this review; retain as a historical FIR blackspot and verify current conditions. | E5: Strong historical evidence; current classification requires new observation or official record. | F5: https://www.inai.ai/img/docs/iraste-nagpur/iRASATE-Detailed-Report.pdf | G5: https://www.inai.ai/img/docs/iraste-nagpur/iRASATE-Detailed-Report.pdf | H5: MEDIUM | I5: Manual map check + current traffic observation
A6: J005 | B6: Chikli Square | C6: Police-FIR blackspot evidence: 31 crashes, 14 fatalities, 18 major injuries and 5 minor injuries in the source table. The location was selected under the report's MoRTH blackspot methodology; the workbook rank is derived from severity outcomes. | D6: 2025 reporting describes major potholes, heavy truck traffic and reported accidents on the Chikhli flyover. | E6: Historical evidence plus newer location-specific support; still verify the latest field condition. | F6: https://www.inai.ai/img/docs/iraste-nagpur/iRASATE-Detailed-Report.pdf | G6: https://timesofindia.indiatimes.com/city/nagpur/chikhli-square-flyover-turns-pothole-maze/articleshow/123210667.cms | H6: MEDIUM-HIGH | I6: Manual map check + current traffic observation
A7: J006 | B7: Maruti Seva Square, Kamptee Road | C7: Police-FIR blackspot evidence: 27 crashes, 11 fatalities, 19 major injuries and 2 minor injuries in the source table. The location was selected under the report's MoRTH blackspot methodology; the workbook rank is derived from severity outcomes. | D7: 2024 traffic-police reporting identifies this as one of two major continuing concerns: 12 serious mishaps, five converging roads, heavy traffic and potholes. | E7: Historical evidence plus newer location-specific support; still verify the latest field condition. | F7: https://www.inai.ai/img/docs/iraste-nagpur/iRASATE-Detailed-Report.pdf | G7: https://www.thehitavada.com/Encyc/2024/12/10/Prakash-High-School-to-Kapsi-Bridge-MarutiShowroom-sq-among.html | H7: MEDIUM-HIGH | I7: Manual map check + current traffic observation
A8: J007 | B8: Shitla Mata Square | C8: Police-FIR blackspot evidence: 27 crashes, 6 fatalities, 27 major injuries and 3 minor injuries in the source table. The location was selected under the report's MoRTH blackspot methodology; the workbook rank is derived from severity outcomes. | D8: No row-specific newer count located; current risk must be verified before claiming it is a present blackspot. | E8: Strong historical evidence; current classification requires new observation or official record. | F8: https://www.inai.ai/img/docs/iraste-nagpur/iRASATE-Detailed-Report.pdf | G8: https://www.inai.ai/img/docs/iraste-nagpur/iRASATE-Detailed-Report.pdf | H8: MEDIUM | I8: Manual map check + current traffic observation
A9: J008 | B9: Kharbi Chowk | C9: Police-FIR blackspot evidence: 21 crashes, 6 fatalities, 16 major injuries and 4 minor injuries in the source table. The location was selected under the report's MoRTH blackspot methodology; the workbook rank is derived from severity outcomes. | D9: No row-specific newer count located; current risk must be verified before claiming it is a present blackspot. | E9: Strong historical evidence; current classification requires new observation or official record. | F9: https://www.inai.ai/img/docs/iraste-nagpur/iRASATE-Detailed-Report.pdf | G9: https://www.inai.ai/img/docs/iraste-nagpur/iRASATE-Detailed-Report.pdf | H9: MEDIUM | I9: Manual map check + current traffic observation
A10: J009 | B10: Mhalgi Nagar Square | C10: Police-FIR blackspot evidence: 18 crashes, 4 fatalities, 18 major injuries and 1 minor injuries in the source table. The location was selected under the report's MoRTH blackspot methodology; the workbook rank is derived from severity outcomes. | D10: The 2021-2023 update lists 2 serious accidents and notes reductions at many treated locations. | E10: Historical evidence plus newer location-specific support; still verify the latest field condition. | F10: https://www.inai.ai/img/docs/iraste-nagpur/iRASATE-Detailed-Report.pdf | G10: https://www.thehitavada.com/Encyc/2024/12/10/Prakash-High-School-to-Kapsi-Bridge-MarutiShowroom-sq-among.html | H10: MEDIUM-HIGH | I10: Manual map check + current traffic observation
A11: J010 | B11: Ravi Nagar | C11: Police-FIR blackspot evidence: 26 crashes, 5 fatalities, 14 major injuries and 7 minor injuries in the source table. The location was selected under the report's MoRTH blackspot methodology; the workbook rank is derived from severity outcomes. | D11: No row-specific newer count located; use as a historical blackspot baseline only. | E11: Strong historical evidence; current classification requires new observation or official record. | F11: https://www.inai.ai/img/docs/iraste-nagpur/iRASATE-Detailed-Report.pdf | G11: https://www.inai.ai/img/docs/iraste-nagpur/iRASATE-Detailed-Report.pdf | H11: MEDIUM | I11: Manual map check + current traffic observation
A12: J011 | B12: Manewada Square | C12: Police-FIR blackspot evidence: 18 crashes, 2 fatalities, 19 major injuries and 3 minor injuries in the source table. The location was selected under the report's MoRTH blackspot methodology; the workbook rank is derived from severity outcomes. | D12: The 2021-2023 update lists 2 serious accidents; risk appears lower than the earlier historical period but still needs monitoring. | E12: Strong historical evidence; current classification requires new observation or official record. | F12: https://www.inai.ai/img/docs/iraste-nagpur/iRASATE-Detailed-Report.pdf | G12: https://www.thehitavada.com/Encyc/2024/12/10/Prakash-High-School-to-Kapsi-Bridge-MarutiShowroom-sq-among.html | H12: MEDIUM | I12: Manual map check + current traffic observation
... A21: J020 | B21: Auto Hub to Toll Naka | C21: Police-FIR blackspot evidence: 12 crashes, 4 fatalities, 10 major injuries and 1 minor injuries in the source table. The location was selected under the report's MoRTH blackspot methodology; the workbook rank is derived from severity outcomes. | D21: No row-specific newer count located; use as historical evidence until a current observation is added. | E21: Strong historical evidence; current classification requires new observation or official record. | F21: https://www.inai.ai/img/docs/iraste-nagpur/iRASATE-Detailed-Report.pdf | G21: https://www.inai.ai/img/docs/iraste-nagpur/iRASATE-Detailed-Report.pdf | H21: MEDIUM | I21: Manual map check + current traffic observation

Sheet Risk_Inputs
A1: Junction_ID | B1: Location_Name | C1: Accident_Factor | D1: Congestion | E1: Violations | F1: Obstruction | G1: Weather | H1: Event | I1: Current_Incident | J1: Coverage_Gap | K1: Risk_Score | L1: Risk_Class | M1: Deployment_Priority | N1: Input_Status | O1: Scenario_Notes
A2: =Junctions_20!A2 -> J001 | B2: =Junctions_20!B2 -> Chhatrapati Square | C2: =Junctions_20!M2/100 -> 1 | K2: =IF(COUNT(C2:I2)=0,"",ROUND(100*(IF(ISNUMBER(C2),C2*Scoring_Config!$B$5,0)+IF(ISNUMBER(D2),D2*Scoring_Config!$B$6,0)+IF(ISNUMBER(E2),E2*Scoring_Config!$B$7,0)+IF(ISNUMBER(F2),F2*Scoring_Config!$B$8,0)+IF(ISNUMBER(G2),G2*Scoring_Config!$B$9,0)+IF(ISNUMBER(H2),H2*Scoring_Config!$B$10,0)+IF(ISNUMBER(I2),I2*Scoring_Config!$B$11,0))/(IF(ISNUMBER(C2),Scoring_Config!$B$5,0)+IF(ISNUMBER(D2),Scoring_Config!$B$6,0)+IF(ISNUMBER(E2),Scoring_Config!$B$7,0)+IF(ISNUMBER(F2),Scoring_Config!$B$8,0)+IF(ISNUMBER(G2),Scoring_Config!$B$9,0)+IF(ISNUMBER(H2),Scoring_Config!$B$10,0)+IF(ISNUMBER(I2),Scoring_Config!$B$11,0)),0)) -> 100 | L2: =IF(K2="","",IF(K2>=80,"CRITICAL",IF(K2>=60,"HIGH",IF(K2>=35,"MEDIUM","LOW")))) -> CRITICAL | M2: =IF(K2="","",ROUND(0.85*K2+15*IF(ISNUMBER(J2),J2,0),0)) -> 85 | N2: =IF(COUNT(D2:J2)=0,"HISTORICAL-ONLY","SCENARIO INPUTS ADDED") -> HISTORICAL-ONLY
A3: =Junctions_20!A3 -> J002 | B3: =Junctions_20!B3 -> Juni Pardi Naka Chowk | C3: =Junctions_20!M3/100 -> 0.81 | K3: =IF(COUNT(C3:I3)=0,"",ROUND(100*(IF(ISNUMBER(C3),C3*Scoring_Config!$B$5,0)+IF(ISNUMBER(D3),D3*Scoring_Config!$B$6,0)+IF(ISNUMBER(E3),E3*Scoring_Config!$B$7,0)+IF(ISNUMBER(F3),F3*Scoring_Config!$B$8,0)+IF(ISNUMBER(G3),G3*Scoring_Config!$B$9,0)+IF(ISNUMBER(H3),H3*Scoring_Config!$B$10,0)+IF(ISNUMBER(I3),I3*Scoring_Config!$B$11,0))/(IF(ISNUMBER(C3),Scoring_Config!$B$5,0)+IF(ISNUMBER(D3),Scoring_Config!$B$6,0)+IF(ISNUMBER(E3),Scoring_Config!$B$7,0)+IF(ISNUMBER(F3),Scoring_Config!$B$8,0)+IF(ISNUMBER(G3),Scoring_Config!$B$9,0)+IF(ISNUMBER(H3),Scoring_Config!$B$10,0)+IF(ISNUMBER(I3),Scoring_Config!$B$11,0)),0)) -> 81 | L3: =IF(K3="","",IF(K3>=80,"CRITICAL",IF(K3>=60,"HIGH",IF(K3>=35,"MEDIUM","LOW")))) -> CRITICAL | M3: =IF(K3="","",ROUND(0.85*K3+15*IF(ISNUMBER(J3),J3,0),0)) -> 69 | N3: =IF(COUNT(D3:J3)=0,"HISTORICAL-ONLY","SCENARIO INPUTS ADDED") -> HISTORICAL-ONLY
A4: =Junctions_20!A4 -> J003 | B4: =Junctions_20!B4 -> Jhansi Rani Square | C4: =Junctions_20!M4/100 -> 0.81 | K4: =IF(COUNT(C4:I4)=0,"",ROUND(100*(IF(ISNUMBER(C4),C4*Scoring_Config!$B$5,0)+IF(ISNUMBER(D4),D4*Scoring_Config!$B$6,0)+IF(ISNUMBER(E4),E4*Scoring_Config!$B$7,0)+IF(ISNUMBER(F4),F4*Scoring_Config!$B$8,0)+IF(ISNUMBER(G4),G4*Scoring_Config!$B$9,0)+IF(ISNUMBER(H4),H4*Scoring_Config!$B$10,0)+IF(ISNUMBER(I4),I4*Scoring_Config!$B$11,0))/(IF(ISNUMBER(C4),Scoring_Config!$B$5,0)+IF(ISNUMBER(D4),Scoring_Config!$B$6,0)+IF(ISNUMBER(E4),Scoring_Config!$B$7,0)+IF(ISNUMBER(F4),Scoring_Config!$B$8,0)+IF(ISNUMBER(G4),Scoring_Config!$B$9,0)+IF(ISNUMBER(H4),Scoring_Config!$B$10,0)+IF(ISNUMBER(I4),Scoring_Config!$B$11,0)),0)) -> 81 | L4: =IF(K4="","",IF(K4>=80,"CRITICAL",IF(K4>=60,"HIGH",IF(K4>=35,"MEDIUM","LOW")))) -> CRITICAL | M4: =IF(K4="","",ROUND(0.85*K4+15*IF(ISNUMBER(J4),J4,0),0)) -> 69 | N4: =IF(COUNT(D4:J4)=0,"HISTORICAL-ONLY","SCENARIO INPUTS ADDED") -> HISTORICAL-ONLY
A5: =Junctions_20!A5 -> J004 | B5: =Junctions_20!B5 -> Jingabai Takli to Zhanda Chowk | C5: =Junctions_20!M5/100 -> 0.79 | K5: =IF(COUNT(C5:I5)=0,"",ROUND(100*(IF(ISNUMBER(C5),C5*Scoring_Config!$B$5,0)+IF(ISNUMBER(D5),D5*Scoring_Config!$B$6,0)+IF(ISNUMBER(E5),E5*Scoring_Config!$B$7,0)+IF(ISNUMBER(F5),F5*Scoring_Config!$B$8,0)+IF(ISNUMBER(G5),G5*Scoring_Config!$B$9,0)+IF(ISNUMBER(H5),H5*Scoring_Config!$B$10,0)+IF(ISNUMBER(I5),I5*Scoring_Config!$B$11,0))/(IF(ISNUMBER(C5),Scoring_Config!$B$5,0)+IF(ISNUMBER(D5),Scoring_Config!$B$6,0)+IF(ISNUMBER(E5),Scoring_Config!$B$7,0)+IF(ISNUMBER(F5),Scoring_Config!$B$8,0)+IF(ISNUMBER(G5),Scoring_Config!$B$9,0)+IF(ISNUMBER(H5),Scoring_Config!$B$10,0)+IF(ISNUMBER(I5),Scoring_Config!$B$11,0)),0)) -> 79 | L5: =IF(K5="","",IF(K5>=80,"CRITICAL",IF(K5>=60,"HIGH",IF(K5>=35,"MEDIUM","LOW")))) -> HIGH | M5: =IF(K5="","",ROUND(0.85*K5+15*IF(ISNUMBER(J5),J5,0),0)) -> 67 | N5: =IF(COUNT(D5:J5)=0,"HISTORICAL-ONLY","SCENARIO INPUTS ADDED") -> HISTORICAL-ONLY
A6: =Junctions_20!A6 -> J005 | B6: =Junctions_20!B6 -> Chikli Square | C6: =Junctions_20!M6/100 -> 0.72 | K6: =IF(COUNT(C6:I6)=0,"",ROUND(100*(IF(ISNUMBER(C6),C6*Scoring_Config!$B$5,0)+IF(ISNUMBER(D6),D6*Scoring_Config!$B$6,0)+IF(ISNUMBER(E6),E6*Scoring_Config!$B$7,0)+IF(ISNUMBER(F6),F6*Scoring_Config!$B$8,0)+IF(ISNUMBER(G6),G6*Scoring_Config!$B$9,0)+IF(ISNUMBER(H6),H6*Scoring_Config!$B$10,0)+IF(ISNUMBER(I6),I6*Scoring_Config!$B$11,0))/(IF(ISNUMBER(C6),Scoring_Config!$B$5,0)+IF(ISNUMBER(D6),Scoring_Config!$B$6,0)+IF(ISNUMBER(E6),Scoring_Config!$B$7,0)+IF(ISNUMBER(F6),Scoring_Config!$B$8,0)+IF(ISNUMBER(G6),Scoring_Config!$B$9,0)+IF(ISNUMBER(H6),Scoring_Config!$B$10,0)+IF(ISNUMBER(I6),Scoring_Config!$B$11,0)),0)) -> 72 | L6: =IF(K6="","",IF(K6>=80,"CRITICAL",IF(K6>=60,"HIGH",IF(K6>=35,"MEDIUM","LOW")))) -> HIGH | M6: =IF(K6="","",ROUND(0.85*K6+15*IF(ISNUMBER(J6),J6,0),0)) -> 61 | N6: =IF(COUNT(D6:J6)=0,"HISTORICAL-ONLY","SCENARIO INPUTS ADDED") -> HISTORICAL-ONLY
A7: =Junctions_20!A7 -> J006 | B7: =Junctions_20!B7 -> Maruti Seva Square, Kamptee Road | C7: =Junctions_20!M7/100 -> 0.63 | K7: =IF(COUNT(C7:I7)=0,"",ROUND(100*(IF(ISNUMBER(C7),C7*Scoring_Config!$B$5,0)+IF(ISNUMBER(D7),D7*Scoring_Config!$B$6,0)+IF(ISNUMBER(E7),E7*Scoring_Config!$B$7,0)+IF(ISNUMBER(F7),F7*Scoring_Config!$B$8,0)+IF(ISNUMBER(G7),G7*Scoring_Config!$B$9,0)+IF(ISNUMBER(H7),H7*Scoring_Config!$B$10,0)+IF(ISNUMBER(I7),I7*Scoring_Config!$B$11,0))/(IF(ISNUMBER(C7),Scoring_Config!$B$5,0)+IF(ISNUMBER(D7),Scoring_Config!$B$6,0)+IF(ISNUMBER(E7),Scoring_Config!$B$7,0)+IF(ISNUMBER(F7),Scoring_Config!$B$8,0)+IF(ISNUMBER(G7),Scoring_Config!$B$9,0)+IF(ISNUMBER(H7),Scoring_Config!$B$10,0)+IF(ISNUMBER(I7),Scoring_Config!$B$11,0)),0)) -> 63 | L7: =IF(K7="","",IF(K7>=80,"CRITICAL",IF(K7>=60,"HIGH",IF(K7>=35,"MEDIUM","LOW")))) -> HIGH | M7: =IF(K7="","",ROUND(0.85*K7+15*IF(ISNUMBER(J7),J7,0),0)) -> 54 | N7: =IF(COUNT(D7:J7)=0,"HISTORICAL-ONLY","SCENARIO INPUTS ADDED") -> HISTORICAL-ONLY
A8: =Junctions_20!A8 -> J007 | B8: =Junctions_20!B8 -> Shitla Mata Square | C8: =Junctions_20!M8/100 -> 0.63 | K8: =IF(COUNT(C8:I8)=0,"",ROUND(100*(IF(ISNUMBER(C8),C8*Scoring_Config!$B$5,0)+IF(ISNUMBER(D8),D8*Scoring_Config!$B$6,0)+IF(ISNUMBER(E8),E8*Scoring_Config!$B$7,0)+IF(ISNUMBER(F8),F8*Scoring_Config!$B$8,0)+IF(ISNUMBER(G8),G8*Scoring_Config!$B$9,0)+IF(ISNUMBER(H8),H8*Scoring_Config!$B$10,0)+IF(ISNUMBER(I8),I8*Scoring_Config!$B$11,0))/(IF(ISNUMBER(C8),Scoring_Config!$B$5,0)+IF(ISNUMBER(D8),Scoring_Config!$B$6,0)+IF(ISNUMBER(E8),Scoring_Config!$B$7,0)+IF(ISNUMBER(F8),Scoring_Config!$B$8,0)+IF(ISNUMBER(G8),Scoring_Config!$B$9,0)+IF(ISNUMBER(H8),Scoring_Config!$B$10,0)+IF(ISNUMBER(I8),Scoring_Config!$B$11,0)),0)) -> 63 | L8: =IF(K8="","",IF(K8>=80,"CRITICAL",IF(K8>=60,"HIGH",IF(K8>=35,"MEDIUM","LOW")))) -> HIGH | M8: =IF(K8="","",ROUND(0.85*K8+15*IF(ISNUMBER(J8),J8,0),0)) -> 54 | N8: =IF(COUNT(D8:J8)=0,"HISTORICAL-ONLY","SCENARIO INPUTS ADDED") -> HISTORICAL-ONLY
A9: =Junctions_20!A9 -> J008 | B9: =Junctions_20!B9 -> Kharbi Chowk | C9: =Junctions_20!M9/100 -> 0.46 | K9: =IF(COUNT(C9:I9)=0,"",ROUND(100*(IF(ISNUMBER(C9),C9*Scoring_Config!$B$5,0)+IF(ISNUMBER(D9),D9*Scoring_Config!$B$6,0)+IF(ISNUMBER(E9),E9*Scoring_Config!$B$7,0)+IF(ISNUMBER(F9),F9*Scoring_Config!$B$8,0)+IF(ISNUMBER(G9),G9*Scoring_Config!$B$9,0)+IF(ISNUMBER(H9),H9*Scoring_Config!$B$10,0)+IF(ISNUMBER(I9),I9*Scoring_Config!$B$11,0))/(IF(ISNUMBER(C9),Scoring_Config!$B$5,0)+IF(ISNUMBER(D9),Scoring_Config!$B$6,0)+IF(ISNUMBER(E9),Scoring_Config!$B$7,0)+IF(ISNUMBER(F9),Scoring_Config!$B$8,0)+IF(ISNUMBER(G9),Scoring_Config!$B$9,0)+IF(ISNUMBER(H9),Scoring_Config!$B$10,0)+IF(ISNUMBER(I9),Scoring_Config!$B$11,0)),0)) -> 46 | L9: =IF(K9="","",IF(K9>=80,"CRITICAL",IF(K9>=60,"HIGH",IF(K9>=35,"MEDIUM","LOW")))) -> MEDIUM | M9: =IF(K9="","",ROUND(0.85*K9+15*IF(ISNUMBER(J9),J9,0),0)) -> 39 | N9: =IF(COUNT(D9:J9)=0,"HISTORICAL-ONLY","SCENARIO INPUTS ADDED") -> HISTORICAL-ONLY
A10: =Junctions_20!A10 -> J009 | B10: =Junctions_20!B10 -> Mhalgi Nagar Square | C10: =Junctions_20!M10/100 -> 0.42 | K10: =IF(COUNT(C10:I10)=0,"",ROUND(100*(IF(ISNUMBER(C10),C10*Scoring_Config!$B$5,0)+IF(ISNUMBER(D10),D10*Scoring_Config!$B$6,0)+IF(ISNUMBER(E10),E10*Scoring_Config!$B$7,0)+IF(ISNUMBER(F10),F10*Scoring_Config!$B$8,0)+IF(ISNUMBER(G10),G10*Scoring_Config!$B$9,0)+IF(ISNUMBER(H10),H10*Scoring_Config!$B$10,0)+IF(ISNUMBER(I10),I10*Scoring_Config!$B$11,0))/(IF(ISNUMBER(C10),Scoring_Config!$B$5,0)+IF(ISNUMBER(D10),Scoring_Config!$B$6,0)+IF(ISNUMBER(E10),Scoring_Config!$B$7,0)+IF(ISNUMBER(F10),Scoring_Config!$B$8,0)+IF(ISNUMBER(G10),Scoring_Config!$B$9,0)+IF(ISNUMBER(H10),Scoring_Config!$B$10,0)+IF(ISNUMBER(I10),Scoring_Config!$B$11,0)),0)) -> 42 | L10: =IF(K10="","",IF(K10>=80,"CRITICAL",IF(K10>=60,"HIGH",IF(K10>=35,"MEDIUM","LOW")))) -> MEDIUM | M10: =IF(K10="","",ROUND(0.85*K10+15*IF(ISNUMBER(J10),J10,0),0)) -> 36 | N10: =IF(COUNT(D10:J10)=0,"HISTORICAL-ONLY","SCENARIO INPUTS ADDED") -> HISTORICAL-ONLY
A11: =Junctions_20!A11 -> J010 | B11: =Junctions_20!B11 -> Ravi Nagar | C11: =Junctions_20!M11/100 -> 0.41 | K11: =IF(COUNT(C11:I11)=0,"",ROUND(100*(IF(ISNUMBER(C11),C11*Scoring_Config!$B$5,0)+IF(ISNUMBER(D11),D11*Scoring_Config!$B$6,0)+IF(ISNUMBER(E11),E11*Scoring_Config!$B$7,0)+IF(ISNUMBER(F11),F11*Scoring_Config!$B$8,0)+IF(ISNUMBER(G11),G11*Scoring_Config!$B$9,0)+IF(ISNUMBER(H11),H11*Scoring_Config!$B$10,0)+IF(ISNUMBER(I11),I11*Scoring_Config!$B$11,0))/(IF(ISNUMBER(C11),Scoring_Config!$B$5,0)+IF(ISNUMBER(D11),Scoring_Config!$B$6,0)+IF(ISNUMBER(E11),Scoring_Config!$B$7,0)+IF(ISNUMBER(F11),Scoring_Config!$B$8,0)+IF(ISNUMBER(G11),Scoring_Config!$B$9,0)+IF(ISNUMBER(H11),Scoring_Config!$B$10,0)+IF(ISNUMBER(I11),Scoring_Config!$B$11,0)),0)) -> 41 | L11: =IF(K11="","",IF(K11>=80,"CRITICAL",IF(K11>=60,"HIGH",IF(K11>=35,"MEDIUM","LOW")))) -> MEDIUM | M11: =IF(K11="","",ROUND(0.85*K11+15*IF(ISNUMBER(J11),J11,0),0)) -> 35 | N11: =IF(COUNT(D11:J11)=0,"HISTORICAL-ONLY","SCENARIO INPUTS ADDED") -> HISTORICAL-ONLY
A12: =Junctions_20!A12 -> J011 | B12: =Junctions_20!B12 -> Manewada Square | C12: =Junctions_20!M12/100 -> 0.39 | K12: =IF(COUNT(C12:I12)=0,"",ROUND(100*(IF(ISNUMBER(C12),C12*Scoring_Config!$B$5,0)+IF(ISNUMBER(D12),D12*Scoring_Config!$B$6,0)+IF(ISNUMBER(E12),E12*Scoring_Config!$B$7,0)+IF(ISNUMBER(F12),F12*Scoring_Config!$B$8,0)+IF(ISNUMBER(G12),G12*Scoring_Config!$B$9,0)+IF(ISNUMBER(H12),H12*Scoring_Config!$B$10,0)+IF(ISNUMBER(I12),I12*Scoring_Config!$B$11,0))/(IF(ISNUMBER(C12),Scoring_Config!$B$5,0)+IF(ISNUMBER(D12),Scoring_Config!$B$6,0)+IF(ISNUMBER(E12),Scoring_Config!$B$7,0)+IF(ISNUMBER(F12),Scoring_Config!$B$8,0)+IF(ISNUMBER(G12),Scoring_Config!$B$9,0)+IF(ISNUMBER(H12),Scoring_Config!$B$10,0)+IF(ISNUMBER(I12),Scoring_Config!$B$11,0)),0)) -> 39 | L12: =IF(K12="","",IF(K12>=80,"CRITICAL",IF(K12>=60,"HIGH",IF(K12>=35,"MEDIUM","LOW")))) -> MEDIUM | M12: =IF(K12="","",ROUND(0.85*K12+15*IF(ISNUMBER(J12),J12,0),0)) -> 33 | N12: =IF(COUNT(D12:J12)=0,"HISTORICAL-ONLY","SCENARIO INPUTS ADDED") -> HISTORICAL-ONLY
A13: =Junctions_20!A13 -> J012 | B13: =Junctions_20!B13 -> Chinchbhavan Square | C13: =Junctions_20!M13/100 -> 0.34 | K13: =IF(COUNT(C13:I13)=0,"",ROUND(100*(IF(ISNUMBER(C13),C13*Scoring_Config!$B$5,0)+IF(ISNUMBER(D13),D13*Scoring_Config!$B$6,0)+IF(ISNUMBER(E13),E13*Scoring_Config!$B$7,0)+IF(ISNUMBER(F13),F13*Scoring_Config!$B$8,0)+IF(ISNUMBER(G13),G13*Scoring_Config!$B$9,0)+IF(ISNUMBER(H13),H13*Scoring_Config!$B$10,0)+IF(ISNUMBER(I13),I13*Scoring_Config!$B$11,0))/(IF(ISNUMBER(C13),Scoring_Config!$B$5,0)+IF(ISNUMBER(D13),Scoring_Config!$B$6,0)+IF(ISNUMBER(E13),Scoring_Config!$B$7,0)+IF(ISNUMBER(F13),Scoring_Config!$B$8,0)+IF(ISNUMBER(G13),Scoring_Config!$B$9,0)+IF(ISNUMBER(H13),Scoring_Config!$B$10,0)+IF(ISNUMBER(I13),Scoring_Config!$B$11,0)),0)) -> 34 | L13: =IF(K13="","",IF(K13>=80,"CRITICAL",IF(K13>=60,"HIGH",IF(K13>=35,"MEDIUM","LOW")))) -> LOW | M13: =IF(K13="","",ROUND(0.85*K13+15*IF(ISNUMBER(J13),J13,0),0)) -> 29 | N13: =IF(COUNT(D13:J13)=0,"HISTORICAL-ONLY","SCENARIO INPUTS ADDED") -> HISTORICAL-ONLY
... A21: =Junctions_20!A21 -> J020 | B21: =Junctions_20!B21 -> Auto Hub to Toll Naka | C21: =Junctions_20!M21/100 -> 0.28 | K21: =IF(COUNT(C21:I21)=0,"",ROUND(100*(IF(ISNUMBER(C21),C21*Scoring_Config!$B$5,0)+IF(ISNUMBER(D21),D21*Scoring_Config!$B$6,0)+IF(ISNUMBER(E21),E21*Scoring_Config!$B$7,0)+IF(ISNUMBER(F21),F21*Scoring_Config!$B$8,0)+IF(ISNUMBER(G21),G21*Scoring_Config!$B$9,0)+IF(ISNUMBER(H21),H21*Scoring_Config!$B$10,0)+IF(ISNUMBER(I21),I21*Scoring_Config!$B$11,0))/(IF(ISNUMBER(C21),Scoring_Config!$B$5,0)+IF(ISNUMBER(D21),Scoring_Config!$B$6,0)+IF(ISNUMBER(E21),Scoring_Config!$B$7,0)+IF(ISNUMBER(F21),Scoring_Config!$B$8,0)+IF(ISNUMBER(G21),Scoring_Config!$B$9,0)+IF(ISNUMBER(H21),Scoring_Config!$B$10,0)+IF(ISNUMBER(I21),Scoring_Config!$B$11,0)),0)) -> 28 | L21: =IF(K21="","",IF(K21>=80,"CRITICAL",IF(K21>=60,"HIGH",IF(K21>=35,"MEDIUM","LOW")))) -> LOW | M21: =IF(K21="","",ROUND(0.85*K21+15*IF(ISNUMBER(J21),J21,0),0)) -> 24 | N21: =IF(COUNT(D21:J21)=0,"HISTORICAL-ONLY","SCENARIO INPUTS ADDED") -> HISTORICAL-ONLY

Sheet Scoring_Config
A1: Risk Scoring Configuration | B1: Risk Scoring Configuration | C1: Risk Scoring Configuration | D1: Risk Scoring Configuration | E1: Risk Scoring Configuration | F1: Risk Scoring Configuration
A2: Risk Scoring Configuration | B2: Risk Scoring Configuration | C2: Risk Scoring Configuration | D2: Risk Scoring Configuration | E2: Risk Scoring Configuration | F2: Risk Scoring Configuration
A4: Factor | B4: Weight | C4: Input range | D4: Meaning | E4: Required provenance | F4: Default
A5: Accident history | B5: 0.3 | C5: 0 to 1 | D5: Historical crash-severity factor derived from the main sheet | E5: REAL/DIRECT or DERIVED from cited crash records | F5: Formula from historical score
A6: Congestion | B6: 0.25 | C6: 0 to 1 | D6: Delay or speed-reduction factor | E6: OBSERVED, REAL API/data or SIMULATED | F6: Blank
A7: Violations | B7: 0.15 | C7: 0 to 1 | D7: Severity-weighted violation factor | E7: REAL aggregate or SIMULATED | F7: Blank
A8: Obstruction | B8: 0.1 | C8: 0 to 1 | D8: Roadwork, pothole, blocked lane or waterlogging | E8: OBSERVED/REAL/SIMULATED | F8: Blank
A9: Weather | B9: 0.05 | C9: 0 to 1 | D9: Rain/visibility severity | E9: IMD/REAL or SIMULATED | F9: Blank
A10: Event | B10: 0.05 | C10: 0 to 1 | D10: Local event pressure | E10: Official notice/OBSERVED/SIMULATED | F10: Blank
A11: Current incident | B11: 0.1 | C11: 0 to 1 | D11: Active incident severity | E11: Commander entry/SIMULATED | F11: Blank
A12: Coverage gap | B12: 0 | C12: 0 to 1 | D12: Used only in deployment priority, not road risk | E12: DERIVED from required and deployed units | F12: Blank
A14: Risk class | B14: Minimum score | C14: Meaning
A15: CRITICAL | B15: 80 | C15: Immediate review; not automatic dispatch
A16: HIGH | B16: 60 | C16: High-priority coverage review
A17: MEDIUM | B17: 35 | C17: Monitor and cover when resources allow
A18: LOW | B18: 0 | C18: Routine monitoring
A20: Important rule | B20: Value
A21: Risk formula | B21: 100 × weighted average of available factors
A22: Deployment priority | B22: 0.85 × Risk Score + 15 × Coverage Gap

Sheet Sources
A1: Source_ID | B1: Publisher | C1: Title | D1: Publication_Date | E1: Geographic_Coverage | F1: Supports | G1: Source_URL | H1: Reliability | I1: Limitations
A2: S01 | B2: iRASTE / INAI consortium | C2: iRASTE Nagpur Detailed Report — Table 4.3 | D2: 2024 | E2: Nagpur city road network | F2: Geocoded blackspot coordinates, crashes, fatalities and injuries | G2: https://www.inai.ai/img/docs/iraste-nagpur/iRASATE-Detailed-Report.pdf | H2: HIGH | I2: Historical data; internal inconsistency in exact FIR date range; requires current verification
A3: S02 | B3: Maharashtra Highway Traffic Police | C3: Maharashtra Black Spot 2021-2023 | D3: 2025-01-08 | E3: Maharashtra police units | F3: Official summary showing 5 Nagpur City blackspots under the reporting framework | G3: https://highwaypolice.maharashtra.gov.in/publication/maharashtra-black-spot-2021-2023/ | H3: HIGH | I3: Summary counts only; does not publish location names on this page
A4: S03 | B4: The Hitavada citing Nagpur Traffic Police | C4: 23 mishap-prone spots update | D4: 2024-12-10 | E4: Nagpur city | F4: Recent serious-accident counts and status for several selected locations | G4: https://www.thehitavada.com/Encyc/2024/12/10/Prakash-High-School-to-Kapsi-Bridge-MarutiShowroom-sq-among.html | H4: MEDIUM-HIGH | I4: News report; only some locations overlap the selected 20
A5: S04 | B5: Nagpur Today citing traffic police | C5: 23 accident-prone black spots | D5: 2022-10-18 | E5: Nagpur city | F5: Police blackspot definition and location-level accident/death/injury table | G5: https://www.nagpurtoday.in/traffic-cops-identify-23-accident-prone-black-spots-on-nagpur-roads/ | H5: MEDIUM | I5: Older snapshot and not an official downloadable dataset
